Workbook
Name PCEntradasN1_Nível_1: TbPCEntradasN1[Nível 1]
Name PCEntradasN1_Nível_1: TbPCEntradasN1[Nível 1]
Name PCEntradasN2_Nível_1: TbPCEntradasN2[Nível 1]
Name PCEntradasN2_Nível_1: TbPCEntradasN2[Nível 1]
Name PCEntradasN2_Nível_2: TbPCEntradasN2[Nível 2]
Name PCEntradasN2_Nível_2: TbPCEntradasN2[Nível 2]
Name PCSaídasN1_Nível_1: TbPCSaídasN1[Nível 1]
Name PCSaídasN1_Nível_1: TbPCSaídasN1[Nível 1]
Name PCSaídasN2_Nível_1: TbPCSaídasN2[Nível 1]
Name PCSaídasN2_Nível_1: TbPCSaídasN2[Nível 1]
Name PCSaídasN2_Nível_2: TbPCSaídasN2[Nível 2]
Name PCSaídasN2_Nível_2: TbPCSaídasN2[Nível 2]
Name Slicer_Ano_Competência: #N/A
Name Slicer_Ano_Competência1: #N/A
Name Slicer_Ano_Previsto: #N/A
Name Slicer_Ano_Previsto1: #N/A
Name Slicer_Ano_Previsto2: #N/A
Name Slicer_Mês_Competência: #N/A
Name Slicer_Mês_Competência1: #N/A
Name Slicer_Mês_Previsto: #N/A
Name Slicer_Mês_Previsto1: #N/A

Sheet Início
B1: Educaçãoweb | N1: FLUXO DE CAIXA EMPRESARIAL
B3: Empresa
B4: LOJAS EDUCANDOWEB LTDA.
B7: Responsável
B8: Victor Von Doom

Sheet Matriz
B1: Educaçãoweb | N1: TÍTULO

Sheet PCEntradasN1
B1: Educaçãoweb | N1: PLANO DE CONTAS DE ENTRADA - Nível 1
B3: PLANO DE CONTAS DE ENTRADA NÍVEL 1
B4: Nível 1
B5: Empréstimos de curto prazo
B6: Financiamentos de longo prazo
B7: Receitas Financeiras
B8: Venda de ativos
B9: Vendas de mercadorias

Sheet PCEntradasN2
B1: Educaçãoweb | N1: PLANO DE CONTAS DE ENTRADA - Nível 2
B3: PLANO DE CONTAS DE ENTRADA NÍVEL 2
B4: Nível 1 | C4: Nível 2
B5: Empréstimos de curto prazo | C5: Empréstimos capital de giro
B6: Receitas Financeiras | C6: Juros sobre aplicações
B7: Venda de ativos | C7: Mobiliário próprio
B8: Vendas de mercadorias | C8: Eletrodomésticos
B9: Vendas de mercadorias | C9: Informática
B10: Vendas de mercadorias | C10: Livros
B11: Vendas de mercadorias | C11: Móveis
B12: Vendas de mercadorias | C12: Som e imagem
B13: Financiamentos de longo prazo | C13: Geral

Sheet PCSaídasN1
B1: Educaçãoweb | N1: PLANO DE CONTAS DE SAÍDA - Nível 1
B3: PLANO DE CONTAS DE SAÍDA NÍVEL 1
B4: Nível 1
B5: Compra de mercadorias
B6: Despesas administrativas
B7: Despesas comerciais
B8: Despesas financeiras
B9: Imposto de renda
B10: Impostos sobre as vendas

Sheet PCSaídasN2
B1: Educaçãoweb | N1: PLANO DE CONTAS DE SAÍDA - Nível 2
B3: PLANO DE CONTAS DE SAÍDA NÍVEL 2
B4: Nível 1 | C4: Nível 2
B5: Compra de mercadorias | C5: Eletrodomésticos
B6: Compra de mercadorias | C6: Informática
B7: Compra de mercadorias | C7: Livros
B8: Compra de mercadorias | C8: Som e imagem
B9: Compra de mercadorias | C9: Vestuário
B10: Despesas administrativas | C10: Comunicação - internet e telefonia
B11: Despesas administrativas | C11: Energia elétrica
B12: Despesas comerciais | C12: Encargos sobre os salários dos vendedores
B13: Despesas comerciais | C13: Salários dos vendedores
B14: Despesas financeiras | C14: Juros sobre empréstimos
B15: Imposto de renda | C15: IR sobre o lucro presumido
B16: Impostos sobre as vendas | C16: Geral

Sheet RegistroEntradas
B1: Educaçãoweb | H1: REGISTRO DAS ENTRADAS DE CAIXA
B3: Data do Caixa Realizado | C3: Data da Competência | D3: Data do Caixa Previsto | E3: Conta Nível 1 | F3: Conta Nível 2 | G3: Histórico | H3: Valor | I3: Mês Caixa | J3: Ano Caixa | K3: Mês Competência | L3: Ano Competência | M3: Mês Previsto | N3: Ano Previsto | O3: Conta Vencida | P3: Venda à Vista | Q3: Dias de Atraso
B4: 42994 | C4: 42957 | D4: 42972 | E4: Vendas de mercadorias | F4: Informática | G4: NF7238 | H4: 1133 | I4: =IF(TbRegistroEntradas[[#This Row],[Data do Caixa Realizado]]="",0,MONTH(TbRegistroEntradas[[#This Row],[Data do Caixa Realizado]])) -> 9 | J4: =IF(TbRegistroEntradas[[#This Row],[Data do Caixa Realizado]]="",0,YEAR(TbRegistroEntradas[[#This Row],[Data do Caixa Realizado]])) -> 2017 | K4: =IF(TbRegistroEntradas[[#This Row],[Data da Competência]]="",0,MONTH(TbRegistroEntradas[[#This Row],[Data da Competência]])) -> 8 | L4: =IF(TbRegistroEntradas[[#This Row],[Data da Competência]]="",0,YEAR(TbRegistroEntradas[[#This Row],[Data da Competência]])) -> 2017 | M4: =IF(TbRegistroEntradas[[#This Row],[Data do Caixa Previsto]]="",0,MONTH(TbRegistroEntradas[[#This Row],[Data do Caixa Previsto]])) -> 8 | N4: =IF(TbRegistroEntradas[[#This Row],[Data do Caixa Previsto]]="",0,YEAR(TbRegistroEntradas[[#This Row],[Data do Caixa Previsto]])) -> 2017 | O4: =IF(AND(TbRegistroEntradas[[#This Row],[Data do Caixa Previsto]]<TODAY(),TbRegistroEntradas[[#This Row],[Data do Caixa Realizado]]=""),"Vencida","Não Vencida") -> Não Vencida | P4: =IF(TbRegistroEntradas[[#This Row],[Data da Competência]]=TbRegistroEntradas[[#This Row],[Data do Caixa Previsto]],"Vista","Prazo") -> Prazo | Q4: =IF(TbRegistroEntradas[[#This Row],[Data do Caixa Realizado]]<>"", IF(TbRegistroEntradas[[#This Row],[Data do Caixa Realizado]]>TbRegistroEntradas[[#This Row],[Data do Caixa Previsto]], TbRegistroEntradas[[#This Row],[Data do Caixa Realizado]]-TbRegistroEntradas[[#This Row],[Data do Caixa Previsto]], 0 ), IF(TODAY()>TbRegistroEntradas[[#This Row],[Data do Caixa Previsto]], TODAY()-TbRegistroEntradas[[#This Row],[Data do Caixa Previsto]], 0 ) ) -> 22
B5: 42985 | C5: 42960 | D5: 42985 | E5: Vendas de mercadorias | F5: Móveis | G5: NF9147 | H5: 164 | I5: =IF(TbRegistroEntradas[[#This Row],[Data do Caixa Realizado]]="",0,MONTH(TbRegistroEntradas[[#This Row],[Data do Caixa Realizado]])) -> 9 | J5: =IF(TbRegistroEntradas[[#This Row],[Data do Caixa Realizado]]="",0,YEAR(TbRegistroEntradas[[#This Row],[Data do Caixa Realizado]])) -> 2017 | K5: =IF(TbRegistroEntradas[[#This Row],[Data da Competência]]="",0,MONTH(TbRegistroEntradas[[#This Row],[Data da Competência]])) -> 8 | L5: =IF(TbRegistroEntradas[[#This Row],[Data da Competência]]="",0,YEAR(TbRegistroEntradas[[#This Row],[Data da Competência]])) -> 2017 | M5: =IF(TbRegistroEntradas[[#This Row],[Data do Caixa Previsto]]="",0,MONTH(TbRegistroEntradas[[#This Row],[Data do Caixa Previsto]])) -> 9 | N5: =IF(TbRegistroEntradas[[#This Row],[Data do Caixa Previsto]]="",0,YEAR(TbRegistroEntradas[[#This Row],[Data do Caixa Previsto]])) -> 2017 | O5: =IF(AND(TbRegistroEntradas[[#This Row],[Data do Caixa Previsto]]<TODAY(),TbRegistroEntradas[[#This Row],[Data do Caixa Realizado]]=""),"Vencida","Não Vencida") -> Não Vencida | P5: =IF(TbRegistroEntradas[[#This Row],[Data da Competência]]=TbRegistroEntradas[[#This Row],[Data do Caixa Previsto]],"Vista","Prazo") -> Prazo | Q5: =IF(TbRegistroEntradas[[#This Row],[Data do Caixa Realizado]]<>"", IF(TbRegistroEntradas[[#This Row],[Data do Caixa Realizado]]>TbRegistroEntradas[[#This Row],[Data do Caixa Previsto]], TbRegistroEntradas[[#This Row],[Data do Caixa Realizado]]-TbRegistroEntradas[[#This Row],[Data do Caixa Previsto]], 0 ), IF(TODAY()>TbRegistroEntradas[[#This Row],[Data do Caixa Previsto]], TODAY()-TbRegistroEntradas[[#This Row],[Data do Caixa Previsto]], 0 ) ) -> 0
B6: 43007 | C6: 42964 | D6: 43001 | E6: Vendas de mercadorias | F6: Móveis | G6: NF8005 | H6: 2937 | I6: =IF(TbRegistroEntradas[[#This Row],[Data do Caixa Realizado]]="",0,MONTH(TbRegistroEntradas[[#This Row],[Data do Caixa Realizado]])) -> 9 | J6: =IF(TbRegistroEntradas[[#This Row],[Data do Caixa Realizado]]="",0,YEAR(TbRegistroEntradas[[#This Row],[Data do Caixa Realizado]])) -> 2017 | K6: =IF(TbRegistroEntradas[[#This Row],[Data da Competência]]="",0,MONTH(TbRegistroEntradas[[#This Row],[Data da Competência]])) -> 8 | L6: =IF(TbRegistroEntradas[[#This Row],[Data da Competência]]="",0,YEAR(TbRegistroEntradas[[#This Row],[Data da Competência]])) -> 2017 | M6: =IF(TbRegistroEntradas[[#This Row],[Data do Caixa Previsto]]="",0,MONTH(TbRegistroEntradas[[#This Row],[Data do Caixa Previsto]])) -> 9 | N6: =IF(TbRegistroEntradas[[#This Row],[Data do Caixa Previsto]]="",0,YEAR(TbRegistroEntradas[[#This Row],[Data do Caixa Previsto]])) -> 2017 | O6: =IF(AND(TbRegistroEntradas[[#This Row],[Data do Caixa Previsto]]<TODAY(),TbRegistroEntradas[[#This Row],[Data do Caixa Realizado]]=""),"Vencida","Não Vencida") -> Não Vencida | P6: =IF(TbRegistroEntradas[[#This Row],[Data da Competência]]=TbRegistroEntradas[[#This Row],[Data do Caixa Previsto]],"Vista","Prazo") -> Prazo | Q6: =IF(TbRegistroEntradas[[#This Row],[Data do Caixa Realizado]]<>"", IF(TbRegistroEntradas[[#This Row],[Data do Caixa Realizado]]>TbRegistroEntradas[[#This Row],[Data do Caixa Previsto]], TbRegistroEntradas[[#This Row],[Data do Caixa Realizado]]-TbRegistroEntradas[[#This Row],[Data do Caixa Previsto]], 0 ), IF(TODAY()>TbRegistroEntradas[[#This Row],[Data do Caixa Previsto]], TODAY()-TbRegistroEntradas[[#This Row],[Data do Caixa Previsto]], 0 ) ) -> 6
B7: 43020 | C7: 42969 | D7: 43020 | E7: Vendas de mercadorias | F7: Som e imagem | G7: NF5493 | H7: 807 | I7: =IF(TbRegistroEntradas[[#This Row],[Data do Caixa Realizado]]="",0,MONTH(TbRegistroEntradas[[#This Row],[Data do Caixa Realizado]])) -> 10 | J7: =IF(TbRegistroEntradas[[#This Row],[Data do Caixa Realizado]]="",0,YEAR(TbRegistroEntradas[[#This Row],[Data do Caixa Realizado]])) -> 2017 | K7: =IF(TbRegistroEntradas[[#This Row],[Data da Competência]]="",0,MONTH(TbRegistroEntradas[[#This Row],[Data da Competência]])) -> 8 | L7: =IF(TbRegistroEntradas[[#This Row],[Data da Competência]]="",0,YEAR(TbRegistroEntradas[[#This Row],[Data da Competência]])) -> 2017 | M7: =IF(TbRegistroEntradas[[#This Row],[Data do Caixa Previsto]]="",0,MONTH(TbRegistroEntradas[[#This Row],[Data do Caixa Previsto]])) -> 10 | N7: =IF(TbRegistroEntradas[[#This Row],[Data do Caixa Previsto]]="",0,YEAR(TbRegistroEntradas[[#This Row],[Data do Caixa Previsto]])) -> 2017 | O7: =IF(AND(TbRegistroEntradas[[#This Row],[Data do Caixa Previsto]]<TODAY(),TbRegistroEntradas[[#This Row],[Data do Caixa Realizado]]=""),"Vencida","Não Vencida") -> Não Vencida | P7: =IF(TbRegistroEntradas[[#This Row],[Data da Competência]]=TbRegistroEntradas[[#This Row],[Data do Caixa Previsto]],"Vista","Prazo") -> Prazo | Q7: =IF(TbRegistroEntradas[[#This Row],[Data do Caixa Realizado]]<>"", IF(TbRegistroEntradas[[#This Row],[Data do Caixa Realizado]]>TbRegistroEntradas[[#This Row],[Data do Caixa Previsto]], TbRegistroEntradas[[#This Row],[Data do Caixa Realizado]]-TbRegistroEntradas[[#This Row],[Data do Caixa Previsto]], 0 ), IF(TODAY()>TbRegistroEntradas[[#This Row],[Data do Caixa Previsto]], TODAY()-TbRegistroEntradas[[#This Row],[Data do Caixa Previsto]], 0 ) ) -> 0
B8: 43014 | C8: 42972 | D8: 43014 | E8: Vendas de mercadorias | F8: Informática | G8: NF7946 | H8: 2612 | I8: =IF(TbRegistroEntradas[[#This Row],[Data do Caixa Realizado]]="",0,MONTH(TbRegistroEntradas[[#This Row],[Data do Caixa Realizado]])) -> 10 | J8: =IF(TbRegistroEntradas[[#This Row],[Data do Caixa Realizado]]="",0,YEAR(TbRegistroEntradas[[#This Row],[Data do Caixa Realizado]])) -> 2017 | K8: =IF(TbRegistroEntradas[[#This Row],[Data da Competência]]="",0,MONTH(TbRegistroEntradas[[#This Row],[Data da Competência]])) -> 8 | L8: =IF(TbRegistroEntradas[[#This Row],[Data da Competência]]="",0,YEAR(TbRegistroEntradas[[#This Row],[Data da Competência]])) -> 2017 | M8: =IF(TbRegistroEntradas[[#This Row],[Data do Caixa Previsto]]="",0,MONTH(TbRegistroEntradas[[#This Row],[Data do Caixa Previsto]])) -> 10 | N8: =IF(TbRegistroEntradas[[#This Row],[Data do Caixa Previsto]]="",0,YEAR(TbRegistroEntradas[[#This Row],[Data do Caixa Previsto]])) -> 2017 | O8: =IF(AND(TbRegistroEntradas[[#This Row],[Data do Caixa Previsto]]<TODAY(),TbRegistroEntradas[[#This Row],[Data do Caixa Realizado]]=""),"Vencida","Não Vencida") -> Não Vencida | P8: =IF(TbRegistroEntradas[[#This Row],[Data da Competência]]=TbRegistroEntradas[[#This Row],[Data do Caixa Previsto]],"Vista","Prazo") -> Prazo | Q8: =IF(TbRegistroEntradas[[#This Row],[Data do Caixa Realizado]]<>"", IF(TbRegistroEntradas[[#This Row],[Data do Caixa Realizado]]>TbRegistroEntradas[[#This Row],[Data do Caixa Previsto]], TbRegistroEntradas[[#This Row],[Data do Caixa Realizado]]-TbRegistroEntradas[[#This Row],[Data do Caixa Previsto]], 0 ), IF(TODAY()>TbRegistroEntradas[[#This Row],[Data do Caixa Previsto]], TODAY()-TbRegistroEntradas[[#This Row],[Data do Caixa Previsto]], 0 ) ) -> 0
B9: 43054 | C9: 42974 | D9: 43030 | E9: Vendas de mercadorias | F9: Móveis | G9: NF8598 | H9: 2483 | I9: =IF(TbRegistroEntradas[[#This Row],[Data do Caixa Realizado]]="",0,MONTH(TbRegistroEntradas[[#This Row],[Data do Caixa Realizado]])) -> 11 | J9: =IF(TbRegistroEntradas[[#This Row],[Data do Caixa Realizado]]="",0,YEAR(TbRegistroEntradas[[#This Row],[Data do Caixa Realizado]])) -> 2017 | K9: =IF(TbRegistroEntradas[[#This Row],[Data da Competência]]="",0,MONTH(TbRegistroEntradas[[#This Row],[Data da Competência]])) -> 8 | L9: =IF(TbRegistroEntradas[[#This Row],[Data da Competência]]="",0,YEAR(TbRegistroEntradas[[#This Row],[Data da Competência]])) -> 2017 | M9: =IF(TbRegistroEntradas[[#This Row],[Data do Caixa Previsto]]="",0,MONTH(TbRegistroEntradas[[#This Row],[Data do Caixa Previsto]])) -> 10 | N9: =IF(TbRegistroEntradas[[#This Row],[Data do Caixa Previsto]]="",0,YEAR(TbRegistroEntradas[[#This Row],[Data do Caixa Previsto]])) -> 2017 | O9: =IF(AND(TbRegistroEntradas[[#This Row],[Data do Caixa Previsto]]<TODAY(),TbRegistroEntradas[[#This Row],[Data do Caixa Realizado]]=""),"Vencida","Não Vencida") -> Não Vencida | P9: =IF(TbRegistroEntradas[[#This Row],[Data da Competência]]=TbRegistroEntradas[[#This Row],[Data do Caixa Previsto]],"Vista","Prazo") -> Prazo | Q9: =IF(TbRegistroEntradas[[#This Row],[Data do Caixa Realizado]]<>"", IF(TbRegistroEntradas[[#This Row],[Data do Caixa Realizado]]>TbRegistroEntradas[[#This Row],[Data do Caixa Previsto]], TbRegistroEntradas[[#This Row],[Data do Caixa Realizado]]-TbRegistroEntradas[[#This Row],[Data do Caixa Previsto]], 0 ), IF(TODAY()>TbRegistroEntradas[[#This Row],[Data do Caixa Previsto]], TODAY()-TbRegistroEntradas[[#This Row],[Data do Caixa Previsto]], 0 ) ) -> 24
B10: 43087 | C10: 42979 | D10: 43009 | E10: Vendas de mercadorias | F10: Informática | G10: NF1535 | H10: 4387 | I10: =IF(TbRegistroEntradas[[#This Row],[Data do Caixa Realizado]]="",0,MONTH(TbRegistroEntradas[[#This Row],[Data do Caixa Realizado]])) -> 12 | J10: =IF(TbRegistroEntradas[[#This Row],[Data do Caixa Realizado]]="",0,YEAR(TbRegistroEntradas[[#This Row],[Data do Caixa Realizado]])) -> 2017 | K10: =IF(TbRegistroEntradas[[#This Row],[Data da Competência]]="",0,MONTH(TbRegistroEntradas[[#This Row],[Data da Competência]])) -> 9 | L10: =IF(TbRegistroEntradas[[#This Row],[Data da Competência]]="",0,YEAR(TbRegistroEntradas[[#This Row],[Data da Competência]])) -> 2017 | M10: =IF(TbRegistroEntradas[[#This Row],[Data do Caixa Previsto]]="",0,MONTH(TbRegistroEntradas[[#This Row],[Data do Caixa Previsto]])) -> 10 | N10: =IF(TbRegistroEntradas[[#This Row],[Data do Caixa Previsto]]="",0,YEAR(TbRegistroEntradas[[#This Row],[Data do Caixa Previsto]])) -> 2017 | O10: =IF(AND(TbRegistroEntradas[[#This Row],[Data do Caixa Previsto]]<TODAY(),TbRegistroEntradas[[#This Row],[Data do Caixa Realizado]]=""),"Vencida","Não Vencida") -> Não Vencida | P10: =IF(TbRegistroEntradas[[#This Row],[Data da Competência]]=TbRegistroEntradas[[#This Row],[Data do Caixa Previsto]],"Vista","Prazo") -> Prazo | Q10: =IF(TbRegistroEntradas[[#This Row],[Data do Caixa Realizado]]<>"", IF(TbRegistroEntradas[[#This Row],[Data do Caixa Realizado]]>TbRegistroEntradas[[#This Row],[Data do Caixa Previsto]], TbRegistroEntradas[[#This Row],[Data do Caixa Realizado]]-TbRegistroEntradas[[#This Row],[Data do Caixa Previsto]], 0 ), IF(TODAY()>TbRegistroEntradas[[#This Row],[Data do Caixa Previsto]], TODAY()-TbRegistroEntradas[[#This Row],[Data do Caixa Previsto]], 0 ) ) -> 78
B11: 43004 | C11: 42980 | D11: 43004 | E11: Vendas de mercadorias | F11: Móveis | G11: NF4333 | H11: 4268 | I11: =IF(TbRegistroEntradas[[#This Row],[Data do Caixa Realizado]]="",0,MONTH(TbRegistroEntradas[[#This Row],[Data do Caixa Realizado]])) -> 9 | J11: =IF(TbRegistroEntradas[[#This Row],[Data do Caixa Realizado]]="",0,YEAR(TbRegistroEntradas[[#This Row],[Data do Caixa Realizado]])) -> 2017 | K11: =IF(TbRegistroEntradas[[#This Row],[Data da Competência]]="",0,MONTH(TbRegistroEntradas[[#This Row],[Data da Competência]])) -> 9 | L11: =IF(TbRegistroEntradas[[#This Row],[Data da Competência]]="",0,YEAR(TbRegistroEntradas[[#This Row],[Data da Competência]])) -> 2017 | M11: =IF(TbRegistroEntradas[[#This Row],[Data do Caixa Previsto]]="",0,MONTH(TbRegistroEntradas[[#This Row],[Data do Caixa Previsto]])) -> 9 | N11: =IF(TbRegistroEntradas[[#This Row],[Data do Caixa Previsto]]="",0,YEAR(TbRegistroEntradas[[#This Row],[Data do Caixa Previsto]])) -> 2017 | O11: =IF(AND(TbRegistroEntradas[[#This Row],[Data do Caixa Previsto]]<TODAY(),TbRegistroEntradas[[#This Row],[Data do Caixa Realizado]]=""),"Vencida","Não Vencida") -> Não Vencida | P11: =IF(TbRegistroEntradas[[#This Row],[Data da Competência]]=TbRegistroEntradas[[#This Row],[Data do Caixa Previsto]],"Vista","Prazo") -> Prazo | Q11: =IF(TbRegistroEntradas[[#This Row],[Data do Caixa Realizado]]<>"", IF(TbRegistroEntradas[[#This Row],[Data do Caixa Realizado]]>TbRegistroEntradas[[#This Row],[Data do Caixa Previsto]], TbRegistroEntradas[[#This Row],[Data do Caixa Realizado]]-TbRegistroEntradas[[#This Row],[Data do Caixa Previsto]], 0 ), IF(TODAY()>TbRegistroEntradas[[#This Row],[Data do Caixa Previsto]], TODAY()-TbRegistroEntradas[[#This Row],[Data do Caixa Previsto]], 0 ) ) -> 0
B12: 43015 | C12: 42984 | D12: 43015 | E12: Vendas de mercadorias | F12: Móveis | G12: NF8091 | H12: 3761 | I12: =IF(TbRegistroEntradas[[#This Row],[Data do Caixa Realizado]]="",0,MONTH(TbRegistroEntradas[[#This Row],[Data do Caixa Realizado]])) -> 10 | J12: =IF(TbRegistroEntradas[[#This Row],[Data do Caixa Realizado]]="",0,YEAR(TbRegistroEntradas[[#This Row],[Data do Caixa Realizado]])) -> 2017 | K12: =IF(TbRegistroEntradas[[#This Row],[Data da Competência]]="",0,MONTH(TbRegistroEntradas[[#This Row],[Data da Competência]])) -> 9 | L12: =IF(TbRegistroEntradas[[#This Row],[Data da Competência]]="",0,YEAR(TbRegistroEntradas[[#This Row],[Data da Competência]])) -> 2017 | M12: =IF(TbRegistroEntradas[[#This Row],[Data do Caixa Previsto]]="",0,MONTH(TbRegistroEntradas[[#This Row],[Data do Caixa Previsto]])) -> 10 | N12: =IF(TbRegistroEntradas[[#This Row],[Data do Caixa Previsto]]="",0,YEAR(TbRegistroEntradas[[#This Row],[Data do Caixa Previsto]])) -> 2017 | O12: =IF(AND(TbRegistroEntradas[[#This Row],[Data do Caixa Previsto]]<TODAY(),TbRegistroEntradas[[#This Row],[Data do Caixa Realizado]]=""),"Vencida","Não Vencida") -> Não Vencida | P12: =IF(TbRegistroEntradas[[#This Row],[Data da Competência]]=TbRegistroEntradas[[#This Row],[Data do Caixa Previsto]],"Vista","Prazo") -> Prazo | Q12: =IF(TbRegistroEntradas[[#This Row],[Data do Caixa Realizado]]<>"", IF(TbRegistroEntradas[[#This Row],[Data do Caixa Realizado]]>TbRegistroEntradas[[#This Row],[Data do Caixa Previsto]], TbRegistroEntradas[[#This Row],[Data do Caixa Realizado]]-TbRegistroEntradas[[#This Row],[Data do Caixa Previsto]], 0 ), IF(TODAY()>TbRegistroEntradas[[#This Row],[Data do Caixa Previsto]], TODAY()-TbRegistroEntradas[[#This Row],[Data do Caixa Previsto]], 0 ) ) -> 0
C13: 42988 | D13: 43013 | E13: Vendas de mercadorias | F13: Móveis | G13: NF2421 | H13: 4983 | I13: =IF(TbRegistroEntradas[[#This Row],[Data do Caixa Realizado]]="",0,MONTH(TbRegistroEntradas[[#This Row],[Data do Caixa Realizado]])) -> 0 | J13: =IF(TbRegistroEntradas[[#This Row],[Data do Caixa Realizado]]="",0,YEAR(TbRegistroEntradas[[#This Row],[Data do Caixa Realizado]])) -> 0 | K13: =IF(TbRegistroEntradas[[#This Row],[Data da Competência]]="",0,MONTH(TbRegistroEntradas[[#This Row],[Data da Competência]])) -> 9 | L13: =IF(TbRegistroEntradas[[#This Row],[Data da Competência]]="",0,YEAR(TbRegistroEntradas[[#This Row],[Data da Competência]])) -> 2017 | M13: =IF(TbRegistroEntradas[[#This Row],[Data do Caixa Previsto]]="",0,MONTH(TbRegistroEntradas[[#This Row],[Data do Caixa Previsto]])) -> 10 | N13: =IF(TbRegistroEntradas[[#This Row],[Data do Caixa Previsto]]="",0,YEAR(TbRegistroEntradas[[#This Row],[Data do Caixa Previsto]])) -> 2017 | O13: =IF(AND(TbRegistroEntradas[[#This Row],[Data do Caixa Previsto]]<TODAY(),TbRegistroEntradas[[#This Row],[Data do Caixa Realizado]]=""),"Vencida","Não Vencida") -> Vencida | P13: =IF(TbRegistroEntradas[[#This Row],[Data da Competência]]=TbRegistroEntradas[[#This Row],[Data do Caixa Previsto]],"Vista","Prazo") -> Prazo | Q13: =IF(TbRegistroEntradas[[#This Row],[Data do Caixa Realizado]]<>"", IF(TbRegistroEntradas[[#This Row],[Data do Caixa Realizado]]>TbRegistroEntradas[[#This Row],[Data do Caixa Previsto]], TbRegistroEntradas[[#This Row],[Data do Caixa Realizado]]-TbRegistroEntradas[[#This Row],[Data do Caixa Previsto]], 0 ), IF(TODAY()>TbRegistroEntradas[[#This Row],[Data do Caixa Previsto]], TODAY()-TbRegistroEntradas[[#This Row],[Data do Caixa Previsto]], 0 ) ) -> 2340
B14: 42997 | C14: 42990 | D14: 42997 | E14: Vendas de mercadorias | F14: Eletrodomésticos | G14: NF9787 | H14: 2502 | I14: =IF(TbRegistroEntradas[[#This Row],[Data do Caixa Realizado]]="",0,MONTH(TbRegistroEntradas[[#This Row],[Data do Caixa Realizado]])) -> 9 | J14: =IF(TbRegistroEntradas[[#This Row],[Data do Caixa Realizado]]="",0,YEAR(TbRegistroEntradas[[#This Row],[Data do Caixa Realizado]])) -> 2017 | K14: =IF(TbRegistroEntradas[[#This Row],[Data da Competência]]="",0,MONTH(TbRegistroEntradas[[#This Row],[Data da Competência]])) -> 9 | L14: =IF(TbRegistroEntradas[[#This Row],[Data da Competência]]="",0,YEAR(TbRegistroEntradas[[#This Row],[Data da Competência]])) -> 2017 | M14: =IF(TbRegistroEntradas[[#This Row],[Data do Caixa Previsto]]="",0,MONTH(TbRegistroEntradas[[#This Row],[Data do Caixa Previsto]])) -> 9 | N14: =IF(TbRegistroEntradas[[#This Row],[Data do Caixa Previsto]]="",0,YEAR(TbRegistroEntradas[[#This Row],[Data do Caixa Previsto]])) -> 2017 | O14: =IF(AND(TbRegistroEntradas[[#This Row],[Data do Caixa Previsto]]<TODAY(),TbRegistroEntradas[[#This Row],[Data do Caixa Realizado]]=""),"Vencida","Não Vencida") -> Não Vencida | P14: =IF(TbRegistroEntradas[[#This Row],[Data da Competência]]=TbRegistroEntradas[[#This Row],[Data do Caixa Previsto]],"Vista","Prazo") -> Prazo | Q14: =IF(TbRegistroEntradas[[#This Row],[Data do Caixa Realizado]]<>"", IF(TbRegistroEntradas[[#This Row],[Data do Caixa Realizado]]>TbRegistroEntradas[[#This Row],[Data do Caixa Previsto]], TbRegistroEntradas[[#This Row],[Data do Caixa Realizado]]-TbRegistroEntradas[[#This Row],[Data do Caixa Previsto]], 0 ), IF(TODAY()>TbRegistroEntradas[[#This Row],[Data do Caixa Previsto]], TODAY()-TbRegistroEntradas[[#This Row],[Data do Caixa Previsto]], 0 ) ) -> 0
B15: 43002 | C15: 42994 | D15: 43002 | E15: Vendas de mercadorias | F15: Móveis | G15: NF8674 | H15: 2337 | I15: =IF(TbRegistroEntradas[[#This Row],[Data do Caixa Realizado]]="",0,MONTH(TbRegistroEntradas[[#This Row],[Data do Caixa Realizado]])) -> 9 | J15: =IF(TbRegistroEntradas[[#This Row],[Data do Caixa Realizado]]="",0,YEAR(TbRegistroEntradas[[#This Row],[Data do Caixa Realizado]])) -> 2017 | K15: =IF(TbRegistroEntradas[[#This Row],[Data da Competência]]="",0,MONTH(TbRegistroEntradas[[#This Row],[Data da Competência]])) -> 9 | L15: =IF(TbRegistroEntradas[[#This Row],[Data da Competência]]="",0,YEAR(TbRegistroEntradas[[#This Row],[Data da Competência]])) -> 2017 | M15: =IF(TbRegistroEntradas[[#This Row],[Data do Caixa Previsto]]="",0,MONTH(TbRegistroEntradas[[#This Row],[Data do Caixa Previsto]])) -> 9 | N15: =IF(TbRegistroEntradas[[#This Row],[Data do Caixa Previsto]]="",0,YEAR(TbRegistroEntradas[[#This Row],[Data do Caixa Previsto]])) -> 2017 | O15: =IF(AND(TbRegistroEntradas[[#This Row],[Data do Caixa Previsto]]<TODAY(),TbRegistroEntradas[[#This Row],[Data do Caixa Realizado]]=""),"Vencida","Não Vencida") -> Não Vencida | P15: =IF(TbRegistroEntradas[[#This Row],[Data da Competência]]=TbRegistroEntradas[[#This Row],[Data do Caixa Previsto]],"Vista","Prazo") -> Prazo | Q15: =IF(TbRegistroEntradas[[#This Row],[Data do Caixa Realizado]]<>"", IF(TbRegistroEntradas[[#This Row],[Data do Caixa Realizado]]>TbRegistroEntradas[[#This Row],[Data do Caixa Previsto]], TbRegistroEntradas[[#This Row],[Data do Caixa Realizado]]-TbRegistroEntradas[[#This Row],[Data do Caixa Previsto]], 0 ), IF(TODAY()>TbRegistroEntradas[[#This Row],[Data do Caixa Previsto]], TODAY()-TbRegistroEntradas[[#This Row],[Data do Caixa Previsto]], 0 ) ) -> 0
B16: 43001 | C16: 43001 | D16: 43001 | E16: Vendas de mercadorias | F16: Livros | G16: NF5880 | H16: 3125 | I16: =IF(TbRegistroEntradas[[#This Row],[Data do Caixa Realizado]]="",0,MONTH(TbRegistroEntradas[[#This Row],[Data do Caixa Realizado]])) -> 9 | J16: =IF(TbRegistroEntradas[[#This Row],[Data do Caixa Realizado]]="",0,YEAR(TbRegistroEntradas[[#This Row],[Data do Caixa Realizado]])) -> 2017 | K16: =IF(TbRegistroEntradas[[#This Row],[Data da Competência]]="",0,MONTH(TbRegistroEntradas[[#This Row],[Data da Competência]])) -> 9 | L16: =IF(TbRegistroEntradas[[#This Row],[Data da Competência]]="",0,YEAR(TbRegistroEntradas[[#This Row],[Data da Competência]])) -> 2017 | M16: =IF(TbRegistroEntradas[[#This Row],[Data do Caixa Previsto]]="",0,MONTH(TbRegistroEntradas[[#This Row],[Data do Caixa Previsto]])) -> 9 | N16: =IF(TbRegistroEntradas[[#This Row],[Data do Caixa Previsto]]="",0,YEAR(TbRegistroEntradas[[#This Row],[Data do Caixa Previsto]])) -> 2017 | O16: =IF(AND(TbRegistroEntradas[[#This Row],[Data do Caixa Previsto]]<TODAY(),TbRegistroEntradas[[#This Row],[Data do Caixa Realizado]]=""),"Vencida","Não Vencida") -> Não Vencida | P16: =IF(TbRegistroEntradas[[#This Row],[Data da Competência]]=TbRegistroEntradas[[#This Row],[Data do Caixa Previsto]],"Vista","Prazo") -> Vista | Q16: =IF(TbRegistroEntradas[[#This Row],[Data do Caixa Realizado]]<>"", IF(TbRegistroEntradas[[#This Row],[Data do Caixa Realizado]]>TbRegistroEntradas[[#This Row],[Data do Caixa Previsto]], TbRegistroEntradas[[#This Row],[Data do Caixa Realizado]]-TbRegistroEntradas[[#This Row],[Data do Caixa Previsto]], 0 ), IF(TODAY()>TbRegistroEntradas[[#This Row],[Data do Caixa Previsto]], TODAY()-TbRegistroEntradas[[#This Row],[Data do Caixa Previsto]], 0 ) ) -> 0
B17: 43056 | C17: 43004 | D17: 43056 | E17: Vendas de mercadorias | F17: Móveis | G17: NF2763 | H17: 1201 | I17: =IF(TbRegistroEntradas[[#This Row],[Data do Caixa Realizado]]="",0,MONTH(TbRegistroEntradas[[#This Row],[Data do Caixa Realizado]])) -> 11 | J17: =IF(TbRegistroEntradas[[#This Row],[Data do Caixa Realizado]]="",0,YEAR(TbRegistroEntradas[[#This Row],[Data do Caixa Realizado]])) -> 2017 | K17: =IF(TbRegistroEntradas[[#This Row],[Data da Competência]]="",0,MONTH(TbRegistroEntradas[[#This Row],[Data da Competência]])) -> 9 | L17: =IF(TbRegistroEntradas[[#This Row],[Data da Competência]]="",0,YEAR(TbRegistroEntradas[[#This Row],[Data da Competência]])) -> 2017 | M17: =IF(TbRegistroEntradas[[#This Row],[Data do Caixa Previsto]]="",0,MONTH(TbRegistroEntradas[[#This Row],[Data do Caixa Previsto]])) -> 11 | N17: =IF(TbRegistroEntradas[[#This Row],[Data do Caixa Previsto]]="",0,YEAR(TbRegistroEntradas[[#This Row],[Data do Caixa Previsto]])) -> 2017 | O17: =IF(AND(TbRegistroEntradas[[#This Row],[Data do Caixa Previsto]]<TODAY(),TbRegistroEntradas[[#This Row],[Data do Caixa Realizado]]=""),"Vencida","Não Vencida") -> Não Vencida | P17: =IF(TbRegistroEntradas[[#This Row],[Data da Competência]]=TbRegistroEntradas[[#This Row],[Data do Caixa Previsto]],"Vista","Prazo") -> Prazo | Q17: =IF(TbRegistroEntradas[[#This Row],[Data do Caixa Realizado]]<>"", IF(TbRegistroEntradas[[#This Row],[Data do Caixa Realizado]]>TbRegistroEntradas[[#This Row],[Data do Caixa Previsto]], TbRegistroEntradas[[#This Row],[Data do Caixa Realizado]]-TbRegistroEntradas[[#This Row],[Data do Caixa Previsto]], 0 ), IF(TODAY()>TbRegistroEntradas[[#This Row],[Data do Caixa Previsto]], TODAY()-TbRegistroEntradas[[#This Row],[Data do Caixa Previsto]], 0 ) ) -> 0
B18: 43018 | C18: 43005 | D18: 43018 | E18: Vendas de mercadorias | F18: Informática | G18: NF3303 | H18: 4380 | I18: =IF(TbRegistroEntradas[[#This Row],[Data do Caixa Realizado]]="",0,MONTH(TbRegistroEntradas[[#This Row],[Data do Caixa Realizado]])) -> 10 | J18: =IF(TbRegistroEntradas[[#This Row],[Data do Caixa Realizado]]="",0,YEAR(TbRegistroEntradas[[#This Row],[Data do Caixa Realizado]])) -> 2017 | K18: =IF(TbRegistroEntradas[[#This Row],[Data da Competência]]="",0,MONTH(TbRegistroEntradas[[#This Row],[Data da Competência]])) -> 9 | L18: =IF(TbRegistroEntradas[[#This Row],[Data da Competência]]="",0,YEAR(TbRegistroEntradas[[#This Row],[Data da Competência]])) -> 2017 | M18: =IF(TbRegistroEntradas[[#This Row],[Data do Caixa Previsto]]="",0,MONTH(TbRegistroEntradas[[#This Row],[Data do Caixa Previsto]])) -> 10 | N18: =IF(TbRegistroEntradas[[#This Row],[Data do Caixa Previsto]]="",0,YEAR(TbRegistroEntradas[[#This Row],[Data do Caixa Previsto]])) -> 2017 | O18: =IF(AND(TbRegistroEntradas[[#This Row],[Data do Caixa Previsto]]<TODAY(),TbRegistroEntradas[[#This Row],[Data do Caixa Realizado]]=""),"Vencida","Não Vencida") -> Não Vencida | P18: =IF(TbRegistroEntradas[[#This Row],[Data da Competência]]=TbRegistroEntradas[[#This Row],[Data do Caixa Previsto]],"Vista","Prazo") -> Prazo | Q18: =IF(TbRegistroEntradas[[#This Row],[Data do Caixa Realizado]]<>"", IF(TbRegistroEntradas[[#This Row],[Data do Caixa Realizado]]>TbRegistroEntradas[[#This Row],[Data do Caixa Previsto]], TbRegistroEntradas[[#This Row],[Data do Caixa Realizado]]-TbRegistroEntradas[[#This Row],[Data do Caixa Previsto]], 0 ), IF(TODAY()>TbRegistroEntradas[[#This Row],[Data do Caixa Previsto]], TODAY()-TbRegistroEntradas[[#This Row],[Data do Caixa Previsto]], 0 ) ) -> 0
B19: 43019 | C19: 43008 | D19: 43019 | E19: Vendas de mercadorias | F19: Livros | G19: NF3966 | H19: 919 | I19: =IF(TbRegistroEntradas[[#This Row],[Data do Caixa Realizado]]="",0,MONTH(TbRegistroEntradas[[#This Row],[Data do Caixa Realizado]])) -> 10 | J19: =IF(TbRegistroEntradas[[#This Row],[Data do Caixa Realizado]]="",0,YEAR(TbRegistroEntradas[[#This Row],[Data do Caixa Realizado]])) -> 2017 | K19: =IF(TbRegistroEntradas[[#This Row],[Data da Competência]]="",0,MONTH(TbRegistroEntradas[[#This Row],[Data da Competência]])) -> 9 | L19: =IF(TbRegistroEntradas[[#This Row],[Data da Competência]]="",0,YEAR(TbRegistroEntradas[[#This Row],[Data da Competência]])) -> 2017 | M19: =IF(TbRegistroEntradas[[#This Row],[Data do Caixa Previsto]]="",0,MONTH(TbRegistroEntradas[[#This Row],[Data do Caixa Previsto]])) -> 10 | N19: =IF(TbRegistroEntradas[[#This Row],[Data do Caixa Previsto]]="",0,YEAR(TbRegistroEntradas[[#This Row],[Data do Caixa Previsto]])) -> 2017 | O19: =IF(AND(TbRegistroEntradas[[#This Row],[Data do Caixa Previsto]]<TODAY(),TbRegistroEntradas[[#This Row],[Data do Caixa Realizado]]=""),"Vencida","Não Vencida") -> Não Vencida | P19: =IF(TbRegistroEntradas[[#This Row],[Data da Competência]]=TbRegistroEntradas[[#This Row],[Data do Caixa Previsto]],"Vista","Prazo") -> Prazo | Q19: =IF(TbRegistroEntradas[[#This Row],[Data do Caixa Realizado]]<>"", IF(TbRegistroEntradas[[#This Row],[Data do Caixa Realizado]]>TbRegistroEntradas[[#This Row],[Data do Caixa Previsto]], TbRegistroEntradas[[#This Row],[Data do Caixa Realizado]]-TbRegistroEntradas[[#This Row],[Data do Caixa Previsto]], 0 ), IF(TODAY()>TbRegistroEntradas[[#This Row],[Data do Caixa Previsto]], TODAY()-TbRegistroEntradas[[#This Row],[Data do Caixa Previsto]], 0 ) ) -> 0
B20: 43076 | C20: 43012 | D20: 43025 | E20: Vendas de mercadorias | F20: Som e imagem | G20: NF6107 | H20: 4590 | I20: =IF(TbRegistroEntradas[[#This Row],[Data do Caixa Realizado]]="",0,MONTH(TbRegistroEntradas[[#This Row],[Data do Caixa Realizado]])) -> 12 | J20: =IF(TbRegistroEntradas[[#This Row],[Data do Caixa Realizado]]="",0,YEAR(TbRegistroEntradas[[#This Row],[Data do Caixa Realizado]])) -> 2017 | K20: =IF(TbRegistroEntradas[[#This Row],[Data da Competência]]="",0,MONTH(TbRegistroEntradas[[#This Row],[Data da Competência]])) -> 10 | L20: =IF(TbRegistroEntradas[[#This Row],[Data da Competência]]="",0,YEAR(TbRegistroEntradas[[#This Row],[Data da Competência]])) -> 2017 | M20: =IF(TbRegistroEntradas[[#This Row],[Data do Caixa Previsto]]="",0,MONTH(TbRegistroEntradas[[#This Row],[Data do Caixa Previsto]])) -> 10 | N20: =IF(TbRegistroEntradas[[#This Row],[Data do Caixa Previsto]]="",0,YEAR(TbRegistroEntradas[[#This Row],[Data do Caixa Previsto]])) -> 2017 | O20: =IF(AND(TbRegistroEntradas[[#This Row],[Data do Caixa Previsto]]<TODAY(),TbRegistroEntradas[[#This Row],[Data do Caixa Realizado]]=""),"Vencida","Não Vencida") -> Não Vencida | P20: =IF(TbRegistroEntradas[[#This Row],[Data da Competência]]=TbRegistroEntradas[[#This Row],[Data do Caixa Previsto]],"Vista","Prazo") -> Prazo | Q20: =IF(TbRegistroEntradas[[#This Row],[Data do Caixa Realizado]]<>"", IF(TbRegistroEntradas[[#This Row],[Data do Caixa Realizado]]>TbRegistroEntradas[[#This Row],[Data do Caixa Previsto]], TbRegistroEntradas[[#This Row],[Data do Caixa Realizado]]-TbRegistroEntradas[[#This Row],[Data do Caixa Previsto]], 0 ), IF(TODAY()>TbRegistroEntradas[[#This Row],[Data do Caixa Previsto]], TODAY()-TbRegistroEntradas[[#This Row],[Data do Caixa Previsto]], 0 ) ) -> 51
B21: 43052 | C21: 43015 | D21: 43052 | E21: Vendas de mercadorias | F21: Eletrodomésticos | G21: NF4832 | H21: 1958 | I21: =IF(TbRegistroEntradas[[#This Row],[Data do Caixa Realizado]]="",0,MONTH(TbRegistroEntradas[[#This Row],[Data do Caixa Realizado]])) -> 11 | J21: =IF(TbRegistroEntradas[[#This Row],[Data do Caixa Realizado]]="",0,YEAR(TbRegistroEntradas[[#This Row],[Data do Caixa Realizado]])) -> 2017 | K21: =IF(TbRegistroEntradas[[#This Row],[Data da Competência]]="",0,MONTH(TbRegistroEntradas[[#This Row],[Data da Competência]])) -> 10 | L21: =IF(TbRegistroEntradas[[#This Row],[Data da Competência]]="",0,YEAR(TbRegistroEntradas[[#This Row],[Data da Competência]])) -> 2017 | M21: =IF(TbRegistroEntradas[[#This Row],[Data do Caixa Previsto]]="",0,MONTH(TbRegistroEntradas[[#This Row],[Data do Caixa Previsto]])) -> 11 | N21: =IF(TbRegistroEntradas[[#This Row],[Data do Caixa Previsto]]="",0,YEAR(TbRegistroEntradas[[#This Row],[Data do Caixa Previsto]])) -> 2017 | O21: =IF(AND(TbRegistroEntradas[[#This Row],[Data do Caixa Previsto]]<TODAY(),TbRegistroEntradas[[#This Row],[Data do Caixa Realizado]]=""),"Vencida","Não Vencida") -> Não Vencida | P21: =IF(TbRegistroEntradas[[#This Row],[Data da Competência]]=TbRegistroEntradas[[#This Row],[Data do Caixa Previsto]],"Vista","Prazo") -> Prazo | Q21: =IF(TbRegistroEntradas[[#This Row],[Data do Caixa Realizado]]<>"", IF(TbRegistroEntradas[[#This Row],[Data do Caixa Realizado]]>TbRegistroEntradas[[#This Row],[Data do Caixa Previsto]], TbRegistroEntradas[[#This Row],[Data do Caixa Realizado]]-TbRegistroEntradas[[#This Row],[Data do Caixa Previsto]], 0 ), IF(TODAY()>TbRegistroEntradas[[#This Row],[Data do Caixa Previsto]], TODAY()-TbRegistroEntradas[[#This Row],[Data do Caixa Previsto]], 0 ) ) -> 0
B22: 43043 | C22: 43017 | D22: 43043 | E22: Vendas de mercadorias | F22: Informática | G22: NF5012 | H22: 1171 | I22: =IF(TbRegistroEntradas[[#This Row],[Data do Caixa Realizado]]="",0,MONTH(TbRegistroEntradas[[#This Row],[Data do Caixa Realizado]])) -> 11 | J22: =IF(TbRegistroEntradas[[#This Row],[Data do Caixa Realizado]]="",0,YEAR(TbRegistroEntradas[[#This Row],[Data do Caixa Realizado]])) -> 2017 | K22: =IF(TbRegistroEntradas[[#This Row],[Data da Competência]]="",0,MONTH(TbRegistroEntradas[[#This Row],[Data da Competência]])) -> 10 | L22: =IF(TbRegistroEntradas[[#This Row],[Data da Competência]]="",0,YEAR(TbRegistroEntradas[[#This Row],[Data da Competência]])) -> 2017 | M22: =IF(TbRegistroEntradas[[#This Row],[Data do Caixa Previsto]]="",0,MONTH(TbRegistroEntradas[[#This Row],[Data do Caixa Previsto]])) -> 11 | N22: =IF(TbRegistroEntradas[[#This Row],[Data do Caixa Previsto]]="",0,YEAR(TbRegistroEntradas[[#This Row],[Data do Caixa Previsto]])) -> 2017 | O22: =IF(AND(TbRegistroEntradas[[#This Row],[Data do Caixa Previsto]]<TODAY(),TbRegistroEntradas[[#This Row],[Data do Caixa Realizado]]=""),"Vencida","Não Vencida") -> Não Vencida | P22: =IF(TbRegistroEntradas[[#This Row],[Data da Competência]]=TbRegistroEntradas[[#This Row],[Data do Caixa Previsto]],"Vista","Prazo") -> Prazo | Q22: =IF(TbRegistroEntradas[[#This Row],[Data do Caixa Realizado]]<>"", IF(TbRegistroEntradas[[#This Row],[Data do Caixa Realizado]]>TbRegistroEntradas[[#This Row],[Data do Caixa Previsto]], TbRegistroEntradas[[#This Row],[Data do Caixa Realizado]]-TbRegistroEntradas[[#This Row],[Data do Caixa Previsto]], 0 ), IF(TODAY()>TbRegistroEntradas[[#This Row],[Data do Caixa Previsto]], TODAY()-TbRegistroEntradas[[#This Row],[Data do Caixa Previsto]], 0 ) ) -> 0
B23: 43060 | C23: 43019 | D23: 43060 | E23: Vendas de mercadorias | F23: Móveis | G23: NF7669 | H23: 2587 | I23: =IF(TbRegistroEntradas[[#This Row],[Data do Caixa Realizado]]="",0,MONTH(TbRegistroEntradas[[#This Row],[Data do Caixa Realizado]])) -> 11 | J23: =IF(TbRegistroEntradas[[#This Row],[Data do Caixa Realizado]]="",0,YEAR(TbRegistroEntradas[[#This Row],[Data do Caixa Realizado]])) -> 2017 | K23: =IF(TbRegistroEntradas[[#This Row],[Data da Competência]]="",0,MONTH(TbRegistroEntradas[[#This Row],[Data da Competência]])) -> 10 | L23: =IF(TbRegistroEntradas[[#This Row],[Data da Competência]]="",0,YEAR(TbRegistroEntradas[[#This Row],[Data da Competência]])) -> 2017 | M23: =IF(TbRegistroEntradas[[#This Row],[Data do Caixa Previsto]]="",0,MONTH(TbRegistroEntradas[[#This Row],[Data do Caixa Previsto]])) -> 11 | N23: =IF(TbRegistroEntradas[[#This Row],[Data do Caixa Previsto]]="",0,YEAR(TbRegistroEntradas[[#This Row],[Data do Caixa Previsto]])) -> 2017 | O23: =IF(AND(TbRegistroEntradas[[#This Row],[Data do Caixa Previsto]]<TODAY(),TbRegistroEntradas[[#This Row],[Data do Caixa Realizado]]=""),"Vencida","Não Vencida") -> Não Vencida | P23: =IF(TbRegistroEntradas[[#This Row],[Data da Competência]]=TbRegistroEntradas[[#This Row],[Data do Caixa Previsto]],"Vista","Prazo") -> Prazo | Q23: =IF(TbRegistroEntradas[[#This Row],[Data do Caixa Realizado]]<>"", IF(TbRegistroEntradas[[#This Row],[Data do Caixa Realizado]]>TbRegistroEntradas[[#This Row],[Data do Caixa Previsto]], TbRegistroEntradas[[#This Row],[Data do Caixa Realizado]]-TbRegistroEntradas[[#This Row],[Data do Caixa Previsto]], 0 ), IF(TODAY()>TbRegistroEntradas[[#This Row],[Data do Caixa Previsto]], TODAY()-TbRegistroEntradas[[#This Row],[Data do Caixa Previsto]], 0 ) ) -> 0
C24: 43023 | D24: 43045 | E24: Vendas de mercadorias | F24: Móveis | G24: NF7663 | H24: 3425 | I24: =IF(TbRegistroEntradas[[#This Row],[Data do Caixa Realizado]]="",0,MONTH(TbRegistroEntradas[[#This Row],[Data do Caixa Realizado]])) -> 0 | J24: =IF(TbRegistroEntradas[[#This Row],[Data do Caixa Realizado]]="",0,YEAR(TbRegistroEntradas[[#This Row],[Data do Caixa Realizado]])) -> 0 | K24: =IF(TbRegistroEntradas[[#This Row],[Data da Competência]]="",0,MONTH(TbRegistroEntradas[[#This Row],[Data da Competência]])) -> 10 | L24: =IF(TbRegistroEntradas[[#This Row],[Data da Competência]]="",0,YEAR(TbRegistroEntradas[[#This Row],[Data da Competência]])) -> 2017 | M24: =IF(TbRegistroEntradas[[#This Row],[Data do Caixa Previsto]]="",0,MONTH(TbRegistroEntradas[[#This Row],[Data do Caixa Previsto]])) -> 11 | N24: =IF(TbRegistroEntradas[[#This Row],[Data do Caixa Previsto]]="",0,YEAR(TbRegistroEntradas[[#This Row],[Data do Caixa Previsto]])) -> 2017 | O24: =IF(AND(TbRegistroEntradas[[#This Row],[Data do Caixa Previsto]]<TODAY(),TbRegistroEntradas[[#This Row],[Data do Caixa Realizado]]=""),"Vencida","Não Vencida") -> Vencida | P24: =IF(TbRegistroEntradas[[#This Row],[Data da Competência]]=TbRegistroEntradas[[#This Row],[Data do Caixa Previsto]],"Vista","Prazo") -> Prazo | Q24: =IF(TbRegistroEntradas[[#This Row],[Data do Caixa Realizado]]<>"", IF(TbRegistroEntradas[[#This Row],[Data do Caixa Realizado]]>TbRegistroEntradas[[#This Row],[Data do Caixa Previsto]], TbRegistroEntradas[[#This Row],[Data do Caixa Realizado]]-TbRegistroEntradas[[#This Row],[Data do Caixa Previsto]], 0 ), IF(TODAY()>TbRegistroEntradas[[#This Row],[Data do Caixa Previsto]], TODAY()-TbRegistroEntradas[[#This Row],[Data do Caixa Previsto]], 0 ) ) -> 2308
B25: 43113 | C25: 43026 | D25: 43026 | E25: Vendas de mercadorias | F25: Som e imagem | G25: NF4063 | H25: 4454 | I25: =IF(TbRegistroEntradas[[#This Row],[Data do Caixa Realizado]]="",0,MONTH(TbRegistroEntradas[[#This Row],[Data do Caixa Realizado]])) -> 1 | J25: =IF(TbRegistroEntradas[[#This Row],[Data do Caixa Realizado]]="",0,YEAR(TbRegistroEntradas[[#This Row],[Data do Caixa Realizado]])) -> 2018 | K25: =IF(TbRegistroEntradas[[#This Row],[Data da Competência]]="",0,MONTH(TbRegistroEntradas[[#This Row],[Data da Competência]])) -> 10 | L25: =IF(TbRegistroEntradas[[#This Row],[Data da Competência]]="",0,YEAR(TbRegistroEntradas[[#This Row],[Data da Competência]])) -> 2017 | M25: =IF(TbRegistroEntradas[[#This Row],[Data do Caixa Previsto]]="",0,MONTH(TbRegistroEntradas[[#This Row],[Data do Caixa Previsto]])) -> 10 | N25: =IF(TbRegistroEntradas[[#This Row],[Data do Caixa Previsto]]="",0,YEAR(TbRegistroEntradas[[#This Row],[Data do Caixa Previsto]])) -> 2017 | O25: =IF(AND(TbRegistroEntradas[[#This Row],[Data do Caixa Previsto]]<TODAY(),TbRegistroEntradas[[#This Row],[Data do Caixa Realizado]]=""),"Vencida","Não Vencida") -> Não Vencida | P25: =IF(TbRegistroEntradas[[#This Row],[Data da Competência]]=TbRegistroEntradas[[#This Row],[Data do Caixa Previsto]],"Vista","Prazo") -> Vista | Q25: =IF(TbRegistroEntradas[[#This Row],[Data do Caixa Realizado]]<>"", IF(TbRegistroEntradas[[#This Row],[Data do Caixa Realizado]]>TbRegistroEntradas[[#This Row],[Data do Caixa Previsto]], TbRegistroEntradas[[#This Row],[Data do Caixa Realizado]]-TbRegistroEntradas[[#This Row],[Data do Caixa Previsto]], 0 ), IF(TODAY()>TbRegistroEntradas[[#This Row],[Data do Caixa Previsto]], TODAY()-TbRegistroEntradas[[#This Row],[Data do Caixa Previsto]], 0 ) ) -> 87
B26: 43030 | C26: 43030 | D26: 43030 | E26: Vendas de mercadorias | F26: Informática | G26: NF4290 | H26: 2134 | I26: =IF(TbRegistroEntradas[[#This Row],[Data do Caixa Realizado]]="",0,MONTH(TbRegistroEntradas[[#This Row],[Data do Caixa Realizado]])) -> 10 | J26: =IF(TbRegistroEntradas[[#This Row],[Data do Caixa Realizado]]="",0,YEAR(TbRegistroEntradas[[#This Row],[Data do Caixa Realizado]])) -> 2017 | K26: =IF(TbRegistroEntradas[[#This Row],[Data da Competência]]="",0,MONTH(TbRegistroEntradas[[#This Row],[Data da Competência]])) -> 10 | L26: =IF(TbRegistroEntradas[[#This Row],[Data da Competência]]="",0,YEAR(TbRegistroEntradas[[#This Row],[Data da Competência]])) -> 2017 | M26: =IF(TbRegistroEntradas[[#This Row],[Data do Caixa Previsto]]="",0,MONTH(TbRegistroEntradas[[#This Row],[Data do Caixa Previsto]])) -> 10 | N26: =IF(TbRegistroEntradas[[#This Row],[Data do Caixa Previsto]]="",0,YEAR(TbRegistroEntradas[[#This Row],[Data do Caixa Previsto]])) -> 2017 | O26: =IF(AND(TbRegistroEntradas[[#This Row],[Data do Caixa Previsto]]<TODAY(),TbRegistroEntradas[[#This Row],[Data do Caixa Realizado]]=""),"Vencida","Não Vencida") -> Não Vencida | P26: =IF(TbRegistroEntradas[[#This Row],[Data da Competência]]=TbRegistroEntradas[[#This Row],[Data do Caixa Previsto]],"Vista","Prazo") -> Vista | Q26: =IF(TbRegistroEntradas[[#This Row],[Data do Caixa Realizado]]<>"", IF(TbRegistroEntradas[[#This Row],[Data do Caixa Realizado]]>TbRegistroEntradas[[#This Row],[Data do Caixa Previsto]], TbRegistroEntradas[[#This Row],[Data do Caixa Realizado]]-TbRegistroEntradas[[#This Row],[Data do Caixa Previsto]], 0 ), IF(TODAY()>TbRegistroEntradas[[#This Row],[Data do Caixa Previsto]], TODAY()-TbRegistroEntradas[[#This Row],[Data do Caixa Previsto]], 0 ) ) -> 0
B27: 43032 | C27: 43032 | D27: 43032 | E27: Vendas de mercadorias | F27: Eletrodomésticos | G27: NF7319 | H27: 257 | I27: =IF(TbRegistroEntradas[[#This Row],[Data do Caixa Realizado]]="",0,MONTH(TbRegistroEntradas[[#This Row],[Data do Caixa Realizado]])) -> 10 | J27: =IF(TbRegistroEntradas[[#This Row],[Data do Caixa Realizado]]="",0,YEAR(TbRegistroEntradas[[#This Row],[Data do Caixa Realizado]])) -> 2017 | K27: =IF(TbRegistroEntradas[[#This Row],[Data da Competência]]="",0,MONTH(TbRegistroEntradas[[#This Row],[Data da Competência]])) -> 10 | L27: =IF(TbRegistroEntradas[[#This Row],[Data da Competência]]="",0,YEAR(TbRegistroEntradas[[#This Row],[Data da Competência]])) -> 2017 | M27: =IF(TbRegistroEntradas[[#This Row],[Data do Caixa Previsto]]="",0,MONTH(TbRegistroEntradas[[#This Row],[Data do Caixa Previsto]])) -> 10 | N27: =IF(TbRegistroEntradas[[#This Row],[Data do Caixa Previsto]]="",0,YEAR(TbRegistroEntradas[[#This Row],[Data do Caixa Previsto]])) -> 2017 | O27: =IF(AND(TbRegistroEntradas[[#This Row],[Data do Caixa Previsto]]<TODAY(),TbRegistroEntradas[[#This Row],[Data do Caixa Realizado]]=""),"Vencida","Não Vencida") -> Não Vencida | P27: =IF(TbRegistroEntradas[[#This Row],[Data da Competência]]=TbRegistroEntradas[[#This Row],[Data do Caixa Previsto]],"Vista","Prazo") -> Vista | Q27: =IF(TbRegistroEntradas[[#This Row],[Data do Caixa Realizado]]<>"", IF(TbRegistroEntradas[[#This Row],[Data do Caixa Realizado]]>TbRegistroEntradas[[#This Row],[Data do Caixa Previsto]], TbRegistroEntradas[[#This Row],[Data do Caixa Realizado]]-TbRegistroEntradas[[#This Row],[Data do Caixa Previsto]], 0 ), IF(TODAY()>TbRegistroEntradas[[#This Row],[Data do Caixa Previsto]], TODAY()-TbRegistroEntradas[[#This Row],[Data do Caixa Previsto]], 0 ) ) -> 0
B28: 43122 | C28: 43032 | D28: 43068 | E28: Vendas de mercadorias | F28: Livros | G28: NF7020 | H28: 2019 | I28: =IF(TbRegistroEntradas[[#This Row],[Data do Caixa Realizado]]="",0,MONTH(TbRegistroEntradas[[#This Row],[Data do Caixa Realizado]])) -> 1 | J28: =IF(TbRegistroEntradas[[#This Row],[Data do Caixa Realizado]]="",0,YEAR(TbRegistroEntradas[[#This Row],[Data do Caixa Realizado]])) -> 2018 | K28: =IF(TbRegistroEntradas[[#This Row],[Data da Competência]]="",0,MONTH(TbRegistroEntradas[[#This Row],[Data da Competência]])) -> 10 | L28: =IF(TbRegistroEntradas[[#This Row],[Data da Competência]]="",0,YEAR(TbRegistroEntradas[[#This Row],[Data da Competência]])) -> 2017 | M28: =IF(TbRegistroEntradas[[#This Row],[Data do Caixa Previsto]]="",0,MONTH(TbRegistroEntradas[[#This Row],[Data do Caixa Previsto]])) -> 11 | N28: =IF(TbRegistroEntradas[[#This Row],[Data do Caixa Previsto]]="",0,YEAR(TbRegistroEntradas[[#This Row],[Data do Caixa Previsto]])) -> 2017 | O28: =IF(AND(TbRegistroEntradas[[#This Row],[Data do Caixa Previsto]]<TODAY(),TbRegistroEntradas[[#This Row],[Data do Caixa Realizado]]=""),"Vencida","Não Vencida") -> Não Vencida | P28: =IF(TbRegistroEntradas[[#This Row],[Data da Competência]]=TbRegistroEntradas[[#This Row],[Data do Caixa Previsto]],"Vista","Prazo") -> Prazo | Q28: =IF(TbRegistroEntradas[[#This Row],[Data do Caixa Realizado]]<>"", IF(TbRegistroEntradas[[#This Row],[Data do Caixa Realizado]]>TbRegistroEntradas[[#This Row],[Data do Caixa Previsto]], TbRegistroEntradas[[#This Row],[Data do Caixa Realizado]]-TbRegistroEntradas[[#This Row],[Data do Caixa Previsto]], 0 ), IF(TODAY()>TbRegistroEntradas[[#This Row],[Data do Caixa Previsto]], TODAY()-TbRegistroEntradas[[#This Row],[Data do Caixa Previsto]], 0 ) ) -> 54
B29: 43034 | C29: 43034 | D29: 43034 | E29: Vendas de mercadorias | F29: Móveis | G29: NF7221 | H29: 3696 | I29: =IF(TbRegistroEntradas[[#This Row],[Data do Caixa Realizado]]="",0,MONTH(TbRegistroEntradas[[#This Row],[Data do Caixa Realizado]])) -> 10 | J29: =IF(TbRegistroEntradas[[#This Row],[Data do Caixa Realizado]]="",0,YEAR(TbRegistroEntradas[[#This Row],[Data do Caixa Realizado]])) -> 2017 | K29: =IF(TbRegistroEntradas[[#This Row],[Data da Competência]]="",0,MONTH(TbRegistroEntradas[[#This Row],[Data da Competência]])) -> 10 | L29: =IF(TbRegistroEntradas[[#This Row],[Data da Competência]]="",0,YEAR(TbRegistroEntradas[[#This Row],[Data da Competência]])) -> 2017 | M29: =IF(TbRegistroEntradas[[#This Row],[Data do Caixa Previsto]]="",0,MONTH(TbRegistroEntradas[[#This Row],[Data do Caixa Previsto]])) -> 10 | N29: =IF(TbRegistroEntradas[[#This Row],[Data do Caixa Previsto]]="",0,YEAR(TbRegistroEntradas[[#This Row],[Data do Caixa Previsto]])) -> 2017 | O29: =IF(AND(TbRegistroEntradas[[#This Row],[Data do Caixa Previsto]]<TODAY(),TbRegistroEntradas[[#This Row],[Data do Caixa Realizado]]=""),"Vencida","Não Vencida") -> Não Vencida | P29: =IF(TbRegistroEntradas[[#This Row],[Data da Competência]]=TbRegistroEntradas[[#This Row],[Data do Caixa Previsto]],"Vista","Prazo") -> Vista | Q29: =IF(TbRegistroEntradas[[#This Row],[Data do Caixa Realizado]]<>"", IF(TbRegistroEntradas[[#This Row],[Data do Caixa Realizado]]>TbRegistroEntradas[[#This Row],[Data do Caixa Previsto]], TbRegistroEntradas[[#This Row],[Data do Caixa Realizado]]-TbRegistroEntradas[[#This Row],[Data do Caixa Previsto]], 0 ), IF(TODAY()>TbRegistroEntradas[[#This Row],[Data do Caixa Previsto]], TODAY()-TbRegistroEntradas[[#This Row],[Data do Caixa Previsto]], 0 ) ) -> 0
B30: 43052 | C30: 43038 | D30: 43052 | E30: Vendas de mercadorias | F30: Livros | G30: NF5004 | H30: 4446 | I30: =IF(TbRegistroEntradas[[#This Row],[Data do Caixa Realizado]]="",0,MONTH(TbRegistroEntradas[[#This Row],[Data do Caixa Realizado]])) -> 11 | J30: =IF(TbRegistroEntradas[[#This Row],[Data do Caixa Realizado]]="",0,YEAR(TbRegistroEntradas[[#This Row],[Data do Caixa Realizado]])) -> 2017 | K30: =IF(TbRegistroEntradas[[#This Row],[Data da Competência]]="",0,MONTH(TbRegistroEntradas[[#This Row],[Data da Competência]])) -> 10 | L30: =IF(TbRegistroEntradas[[#This Row],[Data da Competência]]="",0,YEAR(TbRegistroEntradas[[#This Row],[Data da Competência]])) -> 2017 | M30: =IF(TbRegistroEntradas[[#This Row],[Data do Caixa Previsto]]="",0,MONTH(TbRegistroEntradas[[#This Row],[Data do Caixa Previsto]])) -> 11 | N30: =IF(TbRegistroEntradas[[#This Row],[Data do Caixa Previsto]]="",0,YEAR(TbRegistroEntradas[[#This Row],[Data do Caixa Previsto]])) -> 2017 | O30: =IF(AND(TbRegistroEntradas[[#This Row],[Data do Caixa Previsto]]<TODAY(),TbRegistroEntradas[[#This Row],[Data do Caixa Realizado]]=""),"Vencida","Não Vencida") -> Não Vencida | P30: =IF(TbRegistroEntradas[[#This Row],[Data da Competência]]=TbRegistroEntradas[[#This Row],[Data do Caixa Previsto]],"Vista","Prazo") -> Prazo | Q30: =IF(TbRegistroEntradas[[#This Row],[Data do Caixa Realizado]]<>"", IF(TbRegistroEntradas[[#This Row],[Data do Caixa Realizado]]>TbRegistroEntradas[[#This Row],[Data do Caixa Previsto]], TbRegistroEntradas[[#This Row],[Data do Caixa Realizado]]-TbRegistroEntradas[[#This Row],[Data do Caixa Previsto]], 0 ), IF(TODAY()>TbRegistroEntradas[[#This Row],[Data do Caixa Previsto]], TODAY()-TbRegistroEntradas[[#This Row],[Data do Caixa Previsto]], 0 ) ) -> 0
C31: 43040 | D31: 43057 | E31: Vendas de mercadorias | F31: Livros | G31: NF8690 | H31: 1445 | I31: =IF(TbRegistroEntradas[[#This Row],[Data do Caixa Realizado]]="",0,MONTH(TbRegistroEntradas[[#This Row],[Data do Caixa Realizado]])) -> 0 | J31: =IF(TbRegistroEntradas[[#This Row],[Data do Caixa Realizado]]="",0,YEAR(TbRegistroEntradas[[#This Row],[Data do Caixa Realizado]])) -> 0 | K31: =IF(TbRegistroEntradas[[#This Row],[Data da Competência]]="",0,MONTH(TbRegistroEntradas[[#This Row],[Data da Competência]])) -> 11 | L31: =IF(TbRegistroEntradas[[#This Row],[Data da Competência]]="",0,YEAR(TbRegistroEntradas[[#This Row],[Data da Competência]])) -> 2017 | M31: =IF(TbRegistroEntradas[[#This Row],[Data do Caixa Previsto]]="",0,MONTH(TbRegistroEntradas[[#This Row],[Data do Caixa Previsto]])) -> 11 | N31: =IF(TbRegistroEntradas[[#This Row],[Data do Caixa Previsto]]="",0,YEAR(TbRegistroEntradas[[#This Row],[Data do Caixa Previsto]])) -> 2017 | O31: =IF(AND(TbRegistroEntradas[[#This Row],[Data do Caixa Previsto]]<TODAY(),TbRegistroEntradas[[#This Row],[Data do Caixa Realizado]]=""),"Vencida","Não Vencida") -> Vencida | P31: =IF(TbRegistroEntradas[[#This Row],[Data da Competência]]=TbRegistroEntradas[[#This Row],[Data do Caixa Previsto]],"Vista","Prazo") -> Prazo | Q31: =IF(TbRegistroEntradas[[#This Row],[Data do Caixa Realizado]]<>"", IF(TbRegistroEntradas[[#This Row],[Data do Caixa Realizado]]>TbRegistroEntradas[[#This Row],[Data do Caixa Previsto]], TbRegistroEntradas[[#This Row],[Data do Caixa Realizado]]-TbRegistroEntradas[[#This Row],[Data do Caixa Previsto]], 0 ), IF(TODAY()>TbRegistroEntradas[[#This Row],[Data do Caixa Previsto]], TODAY()-TbRegistroEntradas[[#This Row],[Data do Caixa Previsto]], 0 ) ) -> 2296
B32: 43117 | C32: 43043 | D32: 43068 | E32: Vendas de mercadorias | F32: Informática | G32: NF3424 | H32: 3559 | I32: =IF(TbRegistroEntradas[[#This Row],[Data do Caixa Realizado]]="",0,MONTH(TbRegistroEntradas[[#This Row],[Data do Caixa Realizado]])) -> 1 | J32: =IF(TbRegistroEntradas[[#This Row],[Data do Caixa Realizado]]="",0,YEAR(TbRegistroEntradas[[#This Row],[Data do Caixa Realizado]])) -> 2018 | K32: =IF(TbRegistroEntradas[[#This Row],[Data da Competência]]="",0,MONTH(TbRegistroEntradas[[#This Row],[Data da Competência]])) -> 11 | L32: =IF(TbRegistroEntradas[[#This Row],[Data da Competência]]="",0,YEAR(TbRegistroEntradas[[#This Row],[Data da Competência]])) -> 2017 | M32: =IF(TbRegistroEntradas[[#This Row],[Data do Caixa Previsto]]="",0,MONTH(TbRegistroEntradas[[#This Row],[Data do Caixa Previsto]])) -> 11 | N32: =IF(TbRegistroEntradas[[#This Row],[Data do Caixa Previsto]]="",0,YEAR(TbRegistroEntradas[[#This Row],[Data do Caixa Previsto]])) -> 2017 | O32: =IF(AND(TbRegistroEntradas[[#This Row],[Data do Caixa Previsto]]<TODAY(),TbRegistroEntradas[[#This Row],[Data do Caixa Realizado]]=""),"Vencida","Não Vencida") -> Não Vencida | P32: =IF(TbRegistroEntradas[[#This Row],[Data da Competência]]=TbRegistroEntradas[[#This Row],[Data do Caixa Previsto]],"Vista","Prazo") -> Prazo | Q32: =IF(TbRegistroEntradas[[#This Row],[Data do Caixa Realizado]]<>"", IF(TbRegistroEntradas[[#This Row],[Data do Caixa Realizado]]>TbRegistroEntradas[[#This Row],[Data do Caixa Previsto]], TbRegistroEntradas[[#This Row],[Data do Caixa Realizado]]-TbRegistroEntradas[[#This Row],[Data do Caixa Previsto]], 0 ), IF(TODAY()>TbRegistroEntradas[[#This Row],[Data do Caixa Previsto]], TODAY()-TbRegistroEntradas[[#This Row],[Data do Caixa Previsto]], 0 ) ) -> 49
B33: 43047 | C33: 43047 | D33: 43047 | E33: Vendas de mercadorias | F33: Móveis | G33: NF5808 | H33: 547 | I33: =IF(TbRegistroEntradas[[#This Row],[Data do Caixa Realizado]]="",0,MONTH(TbRegistroEntradas[[#This Row],[Data do Caixa Realizado]])) -> 11 | J33: =IF(TbRegistroEntradas[[#This Row],[Data do Caixa Realizado]]="",0,YEAR(TbRegistroEntradas[[#This Row],[Data do Caixa Realizado]])) -> 2017 | K33: =IF(TbRegistroEntradas[[#This Row],[Data da Competência]]="",0,MONTH(TbRegistroEntradas[[#This Row],[Data da Competência]])) -> 11 | L33: =IF(TbRegistroEntradas[[#This Row],[Data da Competência]]="",0,YEAR(TbRegistroEntradas[[#This Row],[Data da Competência]])) -> 2017 | M33: =IF(TbRegistroEntradas[[#This Row],[Data do Caixa Previsto]]="",0,MONTH(TbRegistroEntradas[[#This Row],[Data do Caixa Previsto]])) -> 11 | N33: =IF(TbRegistroEntradas[[#This Row],[Data do Caixa Previsto]]="",0,YEAR(TbRegistroEntradas[[#This Row],[Data do Caixa Previsto]])) -> 2017 | O33: =IF(AND(TbRegistroEntradas[[#This Row],[Data do Caixa Previsto]]<TODAY(),TbRegistroEntradas[[#This Row],[Data do Caixa Realizado]]=""),"Vencida","Não Vencida") -> Não Vencida | P33: =IF(TbRegistroEntradas[[#This Row],[Data da Competência]]=TbRegistroEntradas[[#This Row],[Data do Caixa Previsto]],"Vista","Prazo") -> Vista | Q33: =IF(TbRegistroEntradas[[#This Row],[Data do Caixa Realizado]]<>"", IF(TbRegistroEntradas[[#This Row],[Data do Caixa Realizado]]>TbRegistroEntradas[[#This Row],[Data do Caixa Previsto]], TbRegistroEntradas[[#This Row],[Data do Caixa Realizado]]-TbRegistroEntradas[[#This Row],[Data do Caixa Previsto]], 0 ), IF(TODAY()>TbRegistroEntradas[[#This Row],[Data do Caixa Previsto]], TODAY()-TbRegistroEntradas[[#This Row],[Data do Caixa Previsto]], 0 ) ) -> 0
B34: 43077 | C34: 43051 | D34: 43051 | E34: Vendas de mercadorias | F34: Móveis | G34: NF2852 | H34: 1221 | I34: =IF(TbRegistroEntradas[[#This Row],[Data do Caixa Realizado]]="",0,MONTH(TbRegistroEntradas[[#This Row],[Data do Caixa Realizado]])) -> 12 | J34: =IF(TbRegistroEntradas[[#This Row],[Data do Caixa Realizado]]="",0,YEAR(TbRegistroEntradas[[#This Row],[Data do Caixa Realizado]])) -> 2017 | K34: =IF(TbRegistroEntradas[[#This Row],[Data da Competência]]="",0,MONTH(TbRegistroEntradas[[#This Row],[Data da Competência]])) -> 11 | L34: =IF(TbRegistroEntradas[[#This Row],[Data da Competência]]="",0,YEAR(TbRegistroEntradas[[#This Row],[Data da Competência]])) -> 2017 | M34: =IF(TbRegistroEntradas[[#This Row],[Data do Caixa Previsto]]="",0,MONTH(TbRegistroEntradas[[#This Row],[Data do Caixa Previsto]])) -> 11 | N34: =IF(TbRegistroEntradas[[#This Row],[Data do Caixa Previsto]]="",0,YEAR(TbRegistroEntradas[[#This Row],[Data do Caixa Previsto]])) -> 2017 | O34: =IF(AND(TbRegistroEntradas[[#This Row],[Data do Caixa Previsto]]<TODAY(),TbRegistroEntradas[[#This Row],[Data do Caixa Realizado]]=""),"Vencida","Não Vencida") -> Não Vencida | P34: =IF(TbRegistroEntradas[[#This Row],[Data da Competência]]=TbRegistroEntradas[[#This Row],[Data do Caixa Previsto]],"Vista","Prazo") -> Vista | Q34: =IF(TbRegistroEntradas[[#This Row],[Data do Caixa Realizado]]<>"", IF(TbRegistroEntradas[[#This Row],[Data do Caixa Realizado]]>TbRegistroEntradas[[#This Row],[Data do Caixa Previsto]], TbRegistroEntradas[[#This Row],[Data do Caixa Realizado]]-TbRegistroEntradas[[#This Row],[Data do Caixa Previsto]], 0 ), IF(TODAY()>TbRegistroEntradas[[#This Row],[Data do Caixa Previsto]], TODAY()-TbRegistroEntradas[[#This Row],[Data do Caixa Previsto]], 0 ) ) -> 26
B35: 43101 | C35: 43053 | D35: 43101 | E35: Vendas de mercadorias | F35: Livros | G35: NF2347 | H35: 4108 | I35: =IF(TbRegistroEntradas[[#This Row],[Data do Caixa Realizado]]="",0,MONTH(TbRegistroEntradas[[#This Row],[Data do Caixa Realizado]])) -> 1 | J35: =IF(TbRegistroEntradas[[#This Row],[Data do Caixa Realizado]]="",0,YEAR(TbRegistroEntradas[[#This Row],[Data do Caixa Realizado]])) -> 2018 | K35: =IF(TbRegistroEntradas[[#This Row],[Data da Competência]]="",0,MONTH(TbRegistroEntradas[[#This Row],[Data da Competência]])) -> 11 | L35: =IF(TbRegistroEntradas[[#This Row],[Data da Competência]]="",0,YEAR(TbRegistroEntradas[[#This Row],[Data da Competência]])) -> 2017 | M35: =IF(TbRegistroEntradas[[#This Row],[Data do Caixa Previsto]]="",0,MONTH(TbRegistroEntradas[[#This Row],[Data do Caixa Previsto]])) -> 1 | N35: =IF(TbRegistroEntradas[[#This Row],[Data do Caixa Previsto]]="",0,YEAR(TbRegistroEntradas[[#This Row],[Data do Caixa Previsto]])) -> 2018 | O35: =IF(AND(TbRegistroEntradas[[#This Row],[Data do Caixa Previsto]]<TODAY(),TbRegistroEntradas[[#This Row],[Data do Caixa Realizado]]=""),"Vencida","Não Vencida") -> Não Vencida | P35: =IF(TbRegistroEntradas[[#This Row],[Data da Competência]]=TbRegistroEntradas[[#This Row],[Data do Caixa Previsto]],"Vista","Prazo") -> Prazo | Q35: =IF(TbRegistroEntradas[[#This Row],[Data do Caixa Realizado]]<>"", IF(TbRegistroEntradas[[#This Row],[Data do Caixa Realizado]]>TbRegistroEntradas[[#This Row],[Data do Caixa Previsto]], TbRegistroEntradas[[#This Row],[Data do Caixa Realizado]]-TbRegistroEntradas[[#This Row],[Data do Caixa Previsto]], 0 ), IF(TODAY()>TbRegistroEntradas[[#This Row],[Data do Caixa Previsto]], TODAY()-TbRegistroEntradas[[#This Row],[Data do Caixa Previsto]], 0 ) ) -> 0
